Workbook

Sheet Valuation Summary
B2: Valuation Summary
B3: Company Analysis
B4: Valuation Date | C4: =Assumptions!C19 -> 45591 | D4: Company Name | E4: =Assumptions!C30 -> Tyson Foods | F4: 52 Week High | G4: =_xlfn.XLOOKUP(F4,Assumptions!$B$33:$B$35,Assumptions!$C$33:$C$35,0) -> 66.88
B5: Team Name | C5: =Assumptions!C25 -> Market Mavericks | D5: Company Ticker | E5: =Assumptions!C31 -> TSN | F5: 52 Week Low | G5: =_xlfn.XLOOKUP(F5,Assumptions!$B$33:$B$35,Assumptions!$C$33:$C$35,0) -> 45.13
B6: Analyst Name | C6: Yash Agrawal | D6: Sector | E6: =Assumptions!C32 -> Consumer Staples | F6: Current Stock Price | G6: =_xlfn.XLOOKUP(F6,Assumptions!$B$33:$B$35,Assumptions!$C$33:$C$35,0) -> 58.67
B8: Valuation Scenarios
B9: Model | C9: Base | D9: Bear | E9: Spread | F9: Bull | G9: Weights | I9: Enter Weights | K9: Y-Values for Secondary Axis
B10: 52 Week Low / High | C10: =_xlfn.XLOOKUP(C9,Assumptions!$D$33:$D$35,Assumptions!$C$33:$C$35,0) -> 58.67 | D10: =_xlfn.XLOOKUP(D9,Assumptions!$D$33:$D$35,Assumptions!$C$33:$C$35,0) -> 45.13 | E10: =F10-D10 -> 21.75 | F10: =_xlfn.XLOOKUP(F9,Assumptions!$D$33:$D$35,Assumptions!$C$33:$C$35,0) -> 66.88 | K10: 1000 | L10: 0 | M10: 0
B11: Perpetuity DCF | C11: =_xlfn.XLOOKUP(C9,'Discounted Cash Flow'!$A$59:$A$61,'Discounted Cash Flow'!$C$59:$C$61,0) -> 92.240402 | D11: =_xlfn.XLOOKUP(D9,'Discounted Cash Flow'!$A$59:$A$61,'Discounted Cash Flow'!$C$59:$C$61,0) -> 90.044447 | E11: =F11-D11 -> 0.26891962 | F11: =_xlfn.XLOOKUP(F9,'Discounted Cash Flow'!$A$59:$A$61,'Discounted Cash Flow'!$C$59:$C$61,0) -> 90.313367 | G11: =I11 -> 0.05 | I11: 0.05 | K11: 1000 | L11: 0 | M11: 0
B12: EBITDA DCF | C12: =_xlfn.XLOOKUP(C9,'Discounted Cash Flow'!$A$59:$A$61,'Discounted Cash Flow'!$F$59:$F$61,0) -> 204.53676 | D12: =_xlfn.XLOOKUP(D9,'Discounted Cash Flow'!$A$59:$A$61,'Discounted Cash Flow'!$F$59:$F$61,0) -> 183.21167 | E12: =F12-D12 -> 40.379345 | F12: =_xlfn.XLOOKUP(F9,'Discounted Cash Flow'!$A$59:$A$61,'Discounted Cash Flow'!$F$59:$F$61,0) -> 223.59102 | G12: =I12 -> 0.15 | I12: 0.15
B13: Comparable Peers | C13: =_xlfn.XLOOKUP(C9,'Comparable Peer'!$A$32:$A$34,'Comparable Peer'!$C$32:$C$34,0) -> 22.52766 | D13: =_xlfn.XLOOKUP(D9,'Comparable Peer'!$A$32:$A$34,'Comparable Peer'!$C$32:$C$34,0) -> -33.107068 | E13: =F13-D13 -> 77.436547 | F13: =_xlfn.XLOOKUP(F9,'Comparable Peer'!$A$32:$A$34,'Comparable Peer'!$C$32:$C$34,0) -> 44.329479 | G13: =I13 -> 0.2 | I13: 0.2
B14: Internal Rate of Return | C14: =_xlfn.XLOOKUP(C9,'Internal Rate of Return'!$A$59:$A$61,'Internal Rate of Return'!$C$59:$C$61,0) -> 84.657 | D14: =_xlfn.XLOOKUP(D9,'Internal Rate of Return'!$A$59:$A$61,'Internal Rate of Return'!$C$59:$C$61,0) -> 82.59764 | E14: =F14-D14 -> -0.0023609774 | F14: =_xlfn.XLOOKUP(F9,'Internal Rate of Return'!$A$59:$A$61,'Internal Rate of Return'!$C$59:$C$61,0) -> 82.595279 | G14: =I14 -> 0.2 | I14: 0.2
B15: Dividend Discount | C15: =_xlfn.XLOOKUP(C9,'Dividend Discount'!$A$53:$A$55,'Dividend Discount'!$C$53:$C$55,0) -> 39.1153 | D15: =_xlfn.XLOOKUP(D9,'Dividend Discount'!$A$53:$A$55,'Dividend Discount'!$C$53:$C$55,0) -> 37.45197 | E15: =F15-D15 -> 3.3881178 | F15: =_xlfn.XLOOKUP(F9,'Dividend Discount'!$A$53:$A$55,'Dividend Discount'!$C$53:$C$55,0) -> 40.840088 | G15: =G16-SUM(G11:G14) -> 0.4
B16: Target Price | C16: =SUMPRODUCT(C11:C15,$G$11:$G$15) -> 72.375586 | D16: =SUMPRODUCT(D11:D15,$G$11:$G$15) -> 56.862876 | E16: =F16-D16 -> 22.912432 | F16: =SUMPRODUCT(F11:F15,$G$11:$G$15) -> 79.775308 | G16: 1 | I16: =+SUM(I11:I15)+G15 -> 1
B18: Current Stock Price versus Scenarios
C19: Current | D19: Bear | E19: Base | F19: Bull
B20: Stock Price | C20: =+$G$6 -> 58.67 | D20: =_xlfn.XLOOKUP(D19,$C$9:$F$9,$C$16:$F$16,0) -> 56.862876 | E20: =_xlfn.XLOOKUP(E19,$C$9:$F$9,$C$16:$F$16,0) -> 72.375586 | F20: =_xlfn.XLOOKUP(F19,$C$9:$F$9,$C$16:$F$16,0) -> 79.775308
B21: Upside (Downside) | D21: =D$20-$C20 -> -1.8071242 | E21: =E$20-$C20 -> 13.705586 | F21: =F$20-$C20 -> 21.105308
B22: Upside (Downside) % | D22: =D$20/$C$20-1 -> -0.030801503 | E22: =E$20/$C$20-1 -> 0.23360468 | F22: =F$20/$C$20-1 -> 0.35972913
B25: Current Stock Price | C25: =$G$6 -> 58.67 | D25: =$G$6 -> 58.67 | E25: =$G$6 -> 58.67 | F25: =$G$6 -> 58.67
B26: Target Price | C26: =$C$16 -> 72.375586 | D26: =$C$16 -> 72.375586 | E26: =$C$16 -> 72.375586 | F26: =$C$16 -> 72.375586

Sheet Assumptions
A2: B | B2: Bloomberg Functions used for this Analysis
B3: Function Description | C3: Function | D3: Template
B4: Financial Analysis | C4: FA
B5: Relative Valuation | C5: RV
B6: Security Description | C6: DES
B7: Company Financials | C7: MODL
B8: Weighted Average Cost of Capital | C8: WACC
B9: Comparable Relative Valuation | C9: EQRV
B11: Excel Template Library | C11: XLTP
B12: =$C$11&" Financial Analysis" -> XLTP Financial Analysis | C12: XFA
B13: =$C$11&" Discounted Cash Flow" -> XLTP Discounted Cash Flow | C13: XDCF
B14: =$C$11&" Bloomberg Comparable Valuation Analysis" -> XLTP Bloomberg Comparable Valuation Analysis | C14: XCVA
A16: A | B16: Assumptions
D17: {=_xlfn.SEQUENCE(1,5+$C$20,(YEAR($C$19)-5))} -> 2019 | E17: 2020 | F17: 2021 | G17: 2022 | H17: 2023 | I17: 2024 | J17: 2025 | K17: 2026 | L17: 2027 | M17: 2028
B18: Valuation Assumptions
B19: Valuation Date | C19: 45591
B20: Number of Forecasted Years | C20: 5 | D20: 3 | E20: 5 | F20: 7 | G20: 10
B21: Exit EV / EBITDA Multiple | C21: 15.97
B24: MSIF Analyst Team | H24: =D64/F64 -> 10.287483
B25: Team Name | C25: Market Mavericks
B26: Analyst Name | C26: Stephen Fredrick
B29: Company Specific Information
B30: Company Name | C30: Tyson Foods
B31: Company Ticker | C31: TSN
B32: Sector | C32: Consumer Staples
B33: 52 Week High | C33: 66.88 | D33: Bull
B34: 52 Week Low | C34: 45.13 | D34: Bear
B35: Current Stock Price | C35: 58.67 | D35: Base
B36: Shares Outstanding | C36: 285.8
B37: Year Ending | C37: 09/31/2024
B38: Currency | C38: USD
B39: ="In "&C38&" " -> In USD | C39: Millions
B42: Dividend Discount Model Assumptions
D43: 1 | E43: 2 | F43: 3 | G43: 4 | H43: 5
D44: {=_xlfn.SEQUENCE(1,5,(YEAR($C$19)-5))} -> 2019 | E44: 2020 | F44: 2021 | G44: 2022 | H44: 2023
B45: Annual Dividend | D45: =(0.42+3*0.375) -> 1.545 | E45: =(0.445+3*0.42) -> 1.705 | F45: =0.46+3*0.445 -> 1.795 | G45: =0.48+3*0.46 -> 1.86 | H45: =0.48+0.48+0.48+0.49 -> 1.93
B46: Compound Annual Growth Rate (CAGR) | C46: =((H45/D45)^(1/H43)-1) -> 0.04550416
B47: Bear | C47: =C46-D47 -> 0.03550416 | D47: 0.01
B48: Bull | C48: =C46+D48 -> 0.05550416 | D48: 0.01
B50: Custom Dividend Growth Rate | C50: 0.04
...

Sheet Discounted Cash Flow
B2: Perpetuity Growth Method - Value Per Share | E2: EBITDA Multiple Method - Value Per Share | H2: Discounted Cash Flow
A3: Base | B3: =_xlfn.TEXTBEFORE(B$2," - ")&" - "&$A3 -> Perpetuity Growth Method - Base | E3: =_xlfn.TEXTBEFORE(E$2," - ")&" - "&$A3 -> EBITDA Multiple Method - Base | H3: =Assumptions!$B$132 -> Year Ending 09/31/2024, In USD Millions | I3: {=_xlfn.SEQUENCE(1,Assumptions!$C$20,(YEAR(Assumptions!$C$19)))} -> 2024 | J3: 2025 | K3: 2026 | L3: 2027 | M3: 2028
B4: ="Free Cash Flow at Year "&COUNTA($I3:$R3) -> Free Cash Flow at Year 5 | C4: {=LOOKUP(2,1/($I15:$R15<>""),$I15:$R15)} -> 2060.8523 | E4: ="Terminal EBITDA at Year "&COUNTA($I3:$R3) -> Terminal EBITDA at Year 5 | F4: {=LOOKUP(2,1/($I4:$R4<>""),$I4:$R4)} -> 5100.4187 | H4: EBITDA | I4: =IF(I3="","",'Income Statement'!H$53) -> 4901.4021 | J4: =IF(J3="","",'Income Statement'!I$53) -> 4950.4161 | K4: =IF(K3="","",'Income Statement'!J$53) -> 4999.9203 | L4: =IF(L3="","",'Income Statement'!K$53) -> 5049.9195 | M4: =IF(M3="","",'Income Statement'!L$53) -> 5100.4187 | N4: =IF(N3="","",'Income Statement'!M$53) | O4: =IF(O3="","",'Income Statement'!N$53) | P4: =IF(P3="","",'Income Statement'!O$53) | ... R4: =IF(R3="","",'Income Statement'!Q$53)
B5: Weighted Average Cost of Capital | C5: =Assumptions!$C$123 -> 0.065769366 | E5: Weighted Average Cost of Capital | F5: =Assumptions!$C$123 -> 0.065769366
B6: Perpetuity Growth Rate | C6: =Assumptions!$C$133 -> 0.01 | E6: Exit EV / EBITDA Multiple | F6: =Assumptions!$C$21 -> 15.97 | H6: NOPAT | I6: =IF(I3="","",'Income Statement'!H$59) -> 2882.3235 | J6: =IF(J3="","",'Income Statement'!I$59) -> 2906.9493 | K6: =IF(K3="","",'Income Statement'!J$59) -> 2935.4675 | L6: =IF(L3="","",'Income Statement'!K$59) -> 2966.6102 | M6: =IF(M3="","",'Income Statement'!L$59) -> 2996.9328 | N6: =IF(N3="","",'Income Statement'!M$59) | O6: =IF(O3="","",'Income Statement'!N$59) | P6: =IF(P3="","",'Income Statement'!O$59) | ... R6: =IF(R3="","",'Income Statement'!Q$59)
B7: =+"Perpetuity Value at Year "&COUNTA($I3:$R3)&" ~ Terminal Value" -> Perpetuity Value at Year 5 ~ Terminal Value | C7: =(C4*(1+C6))/(C5-C6) -> 37322.656 | E7: =+"Perpetuity Value at Year "&COUNTA($I3:$R3)&" ~ Terminal Value" -> Perpetuity Value at Year 5 ~ Terminal Value | F7: =+F4*F6 -> 81453.687
H8: Depreciation and Amortization | I8: =IF(I3="","",'Income Statement'!H$47) -> 1392.2121 | J8: =IF(J3="","",'Income Statement'!I$47) -> 1406.1342 | K8: =IF(K3="","",'Income Statement'!J$47) -> 1420.1956 | L8: =IF(L3="","",'Income Statement'!K$47) -> 1434.3975 | M8: =IF(M3="","",'Income Statement'!L$47) -> 1448.7415 | N8: =IF(N3="","",'Income Statement'!M$47) | O8: =IF(O3="","",'Income Statement'!N$47) | P8: =IF(P3="","",'Income Statement'!O$47) | ... R8: =IF(R3="","",'Income Statement'!Q$47)
B9: Discounted Terminal Value | C9: =C7/(1+C5)^COUNTA($I3:$R3) -> 27142.908 | E9: Discounted Terminal Value | F9: =F7/(1+F5)^COUNTA($I3:$R3) -> 59237.208
B10: Present Value of Free Cash Flows | C10: =SUM($I18:$R18) -> 8803.3986 | E10: Present Value of Free Cash Flows | F10: =SUM($I18:$R18) -> 8803.3986 | H10: Capital Expenditures | I10: =IF(I3="","",'Income Statement'!H$44) -> 1658.1968 | J10: =IF(J3="","",'Income Statement'!I$44) -> 1674.7787 | K10: =IF(K3="","",'Income Statement'!J$44) -> 1691.5265 | L10: =IF(L3="","",'Income Statement'!K$44) -> 1708.4418 | M10: =IF(M3="","",'Income Statement'!L$44) -> 1725.5262 | N10: =IF(N3="","",'Income Statement'!M$44) | O10: =IF(O3="","",'Income Statement'!N$44) | P10: =IF(P3="","",'Income Statement'!O$44) | ... R10: =IF(R3="","",'Income Statement'!Q$44)
B11: Enterprise Value | C11: =C9+C10 -> 35946.307 | E11: Enterprise Value | F11: =F9+F10 -> 68040.607
H12: Net Working Capital Change | I12: =IF(I3="","",'Balance Sheet'!H$47-'Balance Sheet'!G$47) -> 1258.6371 | J12: =IF(J3="","",'Balance Sheet'!I$47-'Balance Sheet'!H$47) -> 1500.5313 | K12: =IF(K3="","",'Balance Sheet'!J$47-'Balance Sheet'!I$47) -> 1176.9184 | L12: =IF(L3="","",'Balance Sheet'!K$47-'Balance Sheet'!J$47) -> 607.51441 | M12: =IF(M3="","",'Balance Sheet'!L$47-'Balance Sheet'!K$47) -> 1314.0402 | N12: =IF(N3="","",'Balance Sheet'!M$47-'Balance Sheet'!L$47) | O12: =IF(O3="","",'Balance Sheet'!N$47-'Balance Sheet'!M$47) | P12: =IF(P3="","",'Balance Sheet'!O$47-'Balance Sheet'!N$47) | ... R12: =IF(R3="","",'Balance Sheet'!Q$47-'Balance Sheet'!P$47)
B13: Net Debt | C13: =+'Balance Sheet'!$G$48 -> 9462 | E13: Net Debt | F13: =+'Balance Sheet'!$G$48 -> 9462
B14: Minority Interest | C14: =+'Balance Sheet'!$G$37 -> 122 | E14: Minority Interest | F14: =+'Balance Sheet'!$G$37 -> 122 | H14: Taxes | I14: =IF(I3="","",'Income Statement'!H$31) -> 626.86646 | J14: =IF(J3="","",'Income Statement'!I$31) -> 637.33259 | K14: =IF(K3="","",'Income Statement'!J$31) -> 644.25721 | L14: =IF(L3="","",'Income Statement'!K$31) -> 648.91174 | M14: =IF(M3="","",'Income Statement'!L$31) -> 654.74439 | N14: =IF(N3="","",'Income Statement'!M$31) | O14: =IF(O3="","",'Income Statement'!N$31) | P14: =IF(P3="","",'Income Statement'!O$31) | ... R14: =IF(R3="","",'Income Statement'!Q$31)
B15: Equity Value | C15: =+C11-C13-C14 -> 26362.307 | E15: Equity Value | F15: =+F11-F13-F14 -> 58456.607 | H15: Free Cash Flow | I15: =IF(I3="","",I6+I8-I10-I12+I14) -> 1984.5683 | J15: =IF(J3="","",J6+J8-J10-J12+J14) -> 1775.1061 | K15: =IF(K3="","",K6+K8-K10-K12+K14) -> 2131.4753 | L15: =IF(L3="","",L6+L8-L10-L12+L14) -> 2733.9633 | M15: =IF(M3="","",M6+M8-M10-M12+M14) -> 2060.8523 | N15: =IF(N3="","",N6+N8-N10-N12+N14) | O15: =IF(O3="","",O6+O8-O10-O12+O14) | P15: =IF(P3="","",P6+P8-P10-P12+P14) | ... R15: =IF(R3="","",R6+R8-R10-R12+R14)
B17: Shares Outstanding | C17: =+Assumptions!$C$36 -> 285.8 | E17: Shares Outstanding | F17: =+Assumptions!$C$36 -> 285.8 | H17: Discount Factor | I17: =IF(I3="","",1/((1+$C5)^COUNTA($I3:I3))) -> 0.93828931 | J17: =IF(J3="","",1/((1+$C5)^COUNTA($I3:J3))) -> 0.88038682 | K17: =IF(K3="","",1/((1+$C5)^COUNTA($I3:K3))) -> 0.82605754 | L17: =IF(L3="","",1/((1+$C5)^COUNTA($I3:L3))) -> 0.77508096 | M17: =IF(M3="","",1/((1+$C5)^COUNTA($I3:M3))) -> 0.72725018 | N17: =IF(N3="","",1/((1+$C5)^COUNTA($I3:N3))) | O17: =IF(O3="","",1/((1+$C5)^COUNTA($I3:O3))) | P17: =IF(P3="","",1/((1+$C5)^COUNTA($I3:P3))) | ... R17: =IF(R3="","",1/((1+$C5)^COUNTA($I3:R3)))
B18: Value Per Share | C18: =+C15/C17 -> 92.240402 | E18: Value Per Share | F18: =+F15/F17 -> 204.53676 | H18: Discounted Free Cash Flow | I18: =IF(I3="","",I15*I17) -> 1862.0992 | J18: =IF(J3="","",J15*J17) -> 1562.78 | K18: =IF(K3="","",K15*K17) -> 1760.7213 | L18: =IF(L3="","",L15*L17) -> 2119.0429 | M18: =IF(M3="","",M15*M17) -> 1498.7552 | N18: =IF(N3="","",N15*N17) | O18: =IF(O3="","",O15*O17) | P18: =IF(P3="","",P15*P17) | ... R18: =IF(R3="","",R15*R17)
A21: Bear | B21: =_xlfn.TEXTBEFORE(B$2," - ")&" - "&$A21 -> Perpetuity Growth Method - Bear | E21: =_xlfn.TEXTBEFORE(E$2," - ")&" - "&$A21 -> EBITDA Multiple Method - Bear | H21: =Assumptions!$B$132 -> Year Ending 09/31/2024, In USD Millions | I21: {=_xlfn.SEQUENCE(1,Assumptions!$C$20,(YEAR(Assumptions!$C$19)))} -> 2024 | J21: 2025 | K21: 2026 | L21: 2027 | M21: 2028
B22: ="Free Cash Flow at Year "&COUNTA($I21:$R21) -> Free Cash Flow at Year 5 | C22: {=LOOKUP(2,1/(I33:R33<>""),I33:R33)} -> 2047.9268 | E22: ="Terminal EBITDA at Year "&COUNTA($I21:$R21) -> Terminal EBITDA at Year 5 | F22: {=LOOKUP(2,1/($I22:$R22<>""),$I22:$R22)} -> 4615.0343 | H22: EBITDA | I22: =IF(I21="","",'IS Bear'!H$53) -> 4804.3446 | J22: =IF(J21="","",'IS Bear'!I$53) -> 4756.3012 | K22: =IF(K21="","",'IS Bear'!J$53) -> 4708.7382 | L22: =IF(L21="","",'IS Bear'!K$53) -> 4661.6508 | M22: =IF(M21="","",'IS Bear'!L$53) -> 4615.0343 | N22: =IF(N21="","",'IS Bear'!M$53) | O22: =IF(O21="","",'IS Bear'!N$53) | P22: =IF(P21="","",'IS Bear'!O$53) | ... R22: =IF(R21="","",'IS Bear'!Q$53)
B23: Weighted Average Cost of Capital | C23: =Assumptions!$C$123 -> 0.065769366 | E23: Weighted Average Cost of Capital | F23: =Assumptions!$C$123 -> 0.065769366
B24: Perpetuity Growth Rate | C24: =Assumptions!$C$133 -> 0.01 | E24: Exit EV / EBITDA Multiple | F24: =Assumptions!$C$21 -> 15.97 | H24: NOPAT | I24: =IF(I21="","",'IS Bear'!H$59) -> 2826.7466 | J24: =IF(J21="","",'IS Bear'!I$59) -> 2795.7954 | K24: =IF(K21="","",'IS Bear'!J$59) -> 2768.7312 | L24: =IF(L21="","",'IS Bear'!K$59) -> 2744.2803 | M24: =IF(M21="","",'IS Bear'!L$59) -> 2718.9926 | N24: =IF(N21="","",'IS Bear'!M$59) | O24: =IF(O21="","",'IS Bear'!N$59) | P24: =IF(P21="","",'IS Bear'!O$59) | ... R24: =IF(R21="","",'IS Bear'!Q$59)
B25: =+"Perpetuity Value at Year "&COUNTA($I21:$R21)&" ~ Terminal Value" -> Perpetuity Value at Year 5 ~ Terminal Value | C25: =(C22*(1+C24))/(C23-C24) -> 37088.571 | E25: =+"Perpetuity Value at Year "&COUNTA($I21:$R21)&" ~ Terminal Value" -> Perpetuity Value at Year 5 ~ Terminal Value | F25: =+F22*F24 -> 73702.098
H26: Depreciation and Amortization | I26: =IF(I21="","",'IS Bear'!H$47) -> 1364.6436 | J26: =IF(J21="","",'IS Bear'!I$47) -> 1350.9971 | K26: =IF(K21="","",'IS Bear'!J$47) -> 1337.4872 | L26: =IF(L21="","",'IS Bear'!K$47) -> 1324.1123 | M26: =IF(M21="","",'IS Bear'!L$47) -> 1310.8712 | N26: =IF(N21="","",'IS Bear'!M$47) | O26: =IF(O21="","",'IS Bear'!N$47) | P26: =IF(P21="","",'IS Bear'!O$47) | ... R26: =IF(R21="","",'IS Bear'!Q$47)
B27: Discounted Terminal Value | C27: =C25/(1+C23)^COUNTA($I21:$R21) -> 26972.67 | E27: Discounted Terminal Value | F27: =F25/(1+F23)^COUNTA($I21:$R21) -> 53599.864
B28: Present Value of Free Cash Flows | C28: =SUM($I36:$R36) -> 8346.0329 | E28: Present Value of Free Cash Flows | F28: =SUM($I36:$R36) -> 8346.0329 | H28: Capital Expenditures | I28: =IF(I21="","",'IS Bear'!H$44) -> 1625.3612 | J28: =IF(J21="","",'IS Bear'!I$44) -> 1609.1076 | K28: =IF(K21="","",'IS Bear'!J$44) -> 1593.0165 | L28: =IF(L21="","",'IS Bear'!K$44) -> 1577.0863 | M28: =IF(M21="","",'IS Bear'!L$44) -> 1561.3155 | N28: =IF(N21="","",'IS Bear'!M$44) | O28: =IF(O21="","",'IS Bear'!N$44) | P28: =IF(P21="","",'IS Bear'!O$44) | ... R28: =IF(R21="","",'IS Bear'!Q$44)
B29: Enterprise Value | C29: =C27+C28 -> 35318.703 | E29: Enterprise Value | F29: =F27+F28 -> 61945.897
H30: Net Working Capital Change | I30: =IF(I21="","",'BS Bear'!H$47-'BS Bear'!G$47) -> 1727.6726 | J30: =IF(J21="","",'BS Bear'!I$47-'BS Bear'!H$47) -> 1335.0183 | K30: =IF(K21="","",'BS Bear'!J$47-'BS Bear'!I$47) -> 963.84522 | L30: =IF(L21="","",'BS Bear'!K$47-'BS Bear'!J$47) -> 346.86436 | M30: =IF(M21="","",'BS Bear'!L$47-'BS Bear'!K$47) -> 1005.792 | N30: =IF(N21="","",'BS Bear'!M$47-'BS Bear'!L$47) | O30: =IF(O21="","",'BS Bear'!N$47-'BS Bear'!M$47) | P30: =IF(P21="","",'BS Bear'!O$47-'BS Bear'!N$47) | ... R30: =IF(R21="","",'BS Bear'!Q$47-'BS Bear'!P$47)
B31: Net Debt | C31: =+'Balance Sheet'!$G$48 -> 9462 | E31: Net Debt | F31: =+'Balance Sheet'!$G$48 -> 9462
B32: Minority Interest | C32: =+'Balance Sheet'!$G$37 -> 122 | E32: Minority Interest | F32: =+'Balance Sheet'!$G$37 -> 122 | H32: Taxes | I32: =IF(I21="","",'IS Bear'!H$31) -> 612.95448 | J32: =IF(J21="","",'IS Bear'!I$31) -> 609.50862 | K32: =IF(K21="","",'IS Bear'!J$31) -> 602.51986 | L32: =IF(L21="","",'IS Bear'!K$31) -> 593.25824 | M32: =IF(M21="","",'IS Bear'!L$31) -> 585.17056 | N32: =IF(N21="","",'IS Bear'!M$31) | O32: =IF(O21="","",'IS Bear'!N$31) | P32: =IF(P21="","",'IS Bear'!O$31) | ... R32: =IF(R21="","",'IS Bear'!Q$31)
B33: Equity Value | C33: =+C29-C31-C32 -> 25734.703 | E33: Equity Value | F33: =+F29-F31-F32 -> 52361.897 | H33: Free Cash Flow | I33: =IF(I21="","",I24+I26-I28-I30+I32) -> 1451.3109 | J33: =IF(J21="","",J24+J26-J28-J30+J32) -> 1812.1753 | K33: =IF(K21="","",K24+K26-K28-K30+K32) -> 2151.8765 | L33: =IF(L21="","",L24+L26-L28-L30+L32) -> 2737.7001 | M33: =IF(M21="","",M24+M26-M28-M30+M32) -> 2047.9268 | N33: =IF(N21="","",N24+N26-N28-N30+N32) | O33: =IF(O21="","",O24+O26-O28-O30+O32) | P33: =IF(P21="","",P24+P26-P28-P30+P32) | ... R33: =IF(R21="","",R24+R26-R28-R30+R32)
B35: Shares Outstanding | C35: =+Assumptions!$C$36 -> 285.8 | E35: Shares Outstanding | F35: =+Assumptions!$C$36 -> 285.8 | H35: Discount Factor | I35: =IF(I21="","",1/((1+$C23)^COUNTA($I21:I21))) -> 0.93828931 | J35: =IF(J21="","",1/((1+$C23)^COUNTA($I21:J21))) -> 0.88038682 | K35: =IF(K21="","",1/((1+$C23)^COUNTA($I21:K21))) -> 0.82605754 | L35: =IF(L21="","",1/((1+$C23)^COUNTA($I21:L21))) -> 0.77508096 | M35: =IF(M21="","",1/((1+$C23)^COUNTA($I21:M21))) -> 0.72725018 | N35: =IF(N21="","",1/((1+$C23)^COUNTA($I21:N21))) | O35: =IF(O21="","",1/((1+$C23)^COUNTA($I21:O21))) | P35: =IF(P21="","",1/((1+$C23)^COUNTA($I21:P21))) | ... R35: =IF(R21="","",1/((1+$C23)^COUNTA($I21:R21)))
B36: Value Per Share | C36: =+C33/C35 -> 90.044447 | E36: Value Per Share | F36: =+F33/F35 -> 183.21167 | H36: Discounted Free Cash Flow | I36: =IF(I21="","",I33*I35) -> 1361.7495 | J36: =IF(J21="","",J33*J35) -> 1595.4153 | K36: =IF(K21="","",K33*K35) -> 1777.5738 | L36: =IF(L21="","",L33*L35) -> 2121.9392 | M36: =IF(M21="","",M33*M35) -> 1489.3552 | N36: =IF(N21="","",N33*N35) | O36: =IF(O21="","",O33*O35) | P36: =IF(P21="","",P33*P35) | ... R36: =IF(R21="","",R33*R35)
A39: Bull | B39: =_xlfn.TEXTBEFORE(B$2," - ")&" - "&$A39 -> Perpetuity Growth Method - Bull | E39: =_xlfn.TEXTBEFORE(E$2," - ")&" - "&$A39 -> EBITDA Multiple Method - Bull | H39: =Assumptions!$B$132 -> Year Ending 09/31/2024, In USD Millions | I39: {=_xlfn.SEQUENCE(1,Assumptions!$C$20,(YEAR(Assumptions!$C$19)))} -> 2024 | J39: 2025 | K39: 2026 | L39: 2027 | M39: 2028
B40: ="Free Cash Flow at Year "&COUNTA($I39:$R39) -> Free Cash Flow at Year 5 | C40: {=LOOKUP(2,1/(I51:R51<>""),I51:R51)} -> 2068.8657 | E40: ="Terminal EBITDA at Year "&COUNTA($I39:$R39) -> Terminal EBITDA at Year 5 | F40: {=LOOKUP(2,1/($I40:$R40<>""),$I40:$R40)} -> 5625.8103 | H40: EBITDA | I40: =IF(I39="","",'IS Bull'!H$53) -> 4998.4596 | J40: =IF(J39="","",'IS Bull'!I$53) -> 5148.4134 | K40: =IF(K39="","",'IS Bull'!J$53) -> 5302.8658 | L40: =IF(L39="","",'IS Bull'!K$53) -> 5461.9517 | M40: =IF(M39="","",'IS Bull'!L$53) -> 5625.8103 | N40: =IF(N39="","",'IS Bull'!M$53) | O40: =IF(O39="","",'IS Bull'!N$53) | P40: =IF(P39="","",'IS Bull'!O$53) | ... R40: =IF(R39="","",'IS Bull'!Q$53)
B41: Weighted Average Cost of Capital | C41: =Assumptions!$C$123 -> 0.065769366 | E41: Weighted Average Cost of Capital | F41: =Assumptions!$C$123 -> 0.065769366
B42: Perpetuity Growth Rate | C42: =Assumptions!$C$133 -> 0.01 | E42: Exit EV / EBITDA Multiple | F42: =Assumptions!$C$21 -> 15.97 | H42: NOPAT | I42: =IF(I39="","",'IS Bull'!H$59) -> 2937.9004 | J42: =IF(J39="","",'IS Bull'!I$59) -> 3020.3262 | K42: =IF(K39="","",'IS Bull'!J$59) -> 3108.9398 | L42: =IF(L39="","",'IS Bull'!K$59) -> 3202.5476 | M42: =IF(M39="","",'IS Bull'!L$59) -> 3297.7819 | N42: =IF(N39="","",'IS Bull'!M$59) | O42: =IF(O39="","",'IS Bull'!N$59) | P42: =IF(P39="","",'IS Bull'!O$59) | ... R42: =IF(R39="","",'IS Bull'!Q$59)
B43: =+"Perpetuity Value at Year "&COUNTA($I39:$R39)&" ~ Terminal Value" -> Perpetuity Value at Year 5 ~ Terminal Value | C43: =(C40*(1+C42))/(C41-C42) -> 37467.781 | E43: =+"Perpetuity Value at Year "&COUNTA($I39:$R39)&" ~ Terminal Value" -> Perpetuity Value at Year 5 ~ Terminal Value | F43: =+F40*F42 -> 89844.19
H44: Depreciation and Amortization | I44: =IF(I39="","",'IS Bull'!H$47) -> 1419.7807 | J44: =IF(J39="","",'IS Bull'!I$47) -> 1462.3741 | K44: =IF(K39="","",'IS Bull'!J$47) -> 1506.2453 | L44: =IF(L39="","",'IS Bull'!K$47) -> 1551.4327 | M44: =IF(M39="","",'IS Bull'!L$47) -> 1597.9757 | N44: =IF(N39="","",'IS Bull'!M$47) | O44: =IF(O39="","",'IS Bull'!N$47) | P44: =IF(P39="","",'IS Bull'!O$47) | ... R44: =IF(R39="","",'IS Bull'!Q$47)
B45: Discounted Terminal Value | C45: =C43/(1+C41)^COUNTA($I39:$R39) -> 27248.45 | E45: Discounted Terminal Value | F45: =F43/(1+F41)^COUNTA($I39:$R39) -> 65339.203
B46: Present Value of Free Cash Flows | C46: =SUM($I54:$R54) -> 8147.11 | E46: Present Value of Free Cash Flows | F46: =SUM($I54:$R54) -> 8147.11 | H46: Capital Expenditures | I46: =IF(I39="","",'IS Bull'!H$44) -> 1691.0323 | J46: =IF(J39="","",'IS Bull'!I$44) -> 1741.7633 | K46: =IF(K39="","",'IS Bull'!J$44) -> 1794.0162 | L46: =IF(L39="","",'IS Bull'!K$44) -> 1847.8367 | M46: =IF(M39="","",'IS Bull'!L$44) -> 1903.2718 | N46: =IF(N39="","",'IS Bull'!M$44) | O46: =IF(O39="","",'IS Bull'!N$44) | P46: =IF(P39="","",'IS Bull'!O$44) | ... R46: =IF(R39="","",'IS Bull'!Q$44)
B47: Enterprise Value | C47: =C45+C46 -> 35395.56 | E47: Enterprise Value | F47: =F45+F46 -> 73486.313
...

Sheet Comparable Peer
B2: Comparable Peer Companies
B3: Market and Financial Data - In Millions USD
B4: Company Name | C4: Enterprise Value | D4: LTM Sales | E4: LTM EBITDA | F4: Earnings | G4: EV / Sales | H4: EV / EBITDA | I4: P / E
B5: Target Company
B6: =Assumptions!$C$30 -> Tyson Foods | C6: =Assumptions!D64 -> 30327.5 | D6: =Assumptions!E64 -> 53092 | E6: =Assumptions!F64 -> 2948 | F6: =+'Income Statement'!$G$37 -> -648 | G6: =IFERROR(C6/D6,0) -> 0.57122542 | H6: =IFERROR(C6/E6,0) -> 10.287483 | I6: =Assumptions!C64 -> 24.6
B7: Comparable Peer Companies
B8: =Assumptions!B66 -> Pilgrim's Pride | C8: =Assumptions!D66 -> 13208.2 | D8: =Assumptions!E66 -> 17809.7 | E8: =Assumptions!F66 -> 1678.3 | G8: =IFERROR(C8/D8,0) -> 0.74162956 | H8: =IFERROR(C8/E8,0) -> 7.8699875 | I8: =Assumptions!C66 -> 12.1
B9: =Assumptions!B67 -> Hormel Foods Corp | C9: =Assumptions!D67 -> 19340.2 | D9: =Assumptions!E67 -> 11980.8 | E9: =Assumptions!F67 -> 1307.8 | G9: =IFERROR(C9/D9,0) -> 1.6142662 | H9: =IFERROR(C9/E9,0) -> 14.788347 | I9: =Assumptions!C67 -> 18.4
B10: =Assumptions!B68 -> Maple Leaf | C10: =Assumptions!D68 -> 4577 | D10: =Assumptions!E68 -> 4851.9 | E10: =Assumptions!F68 -> 499.7 | G10: =IFERROR(C10/D10,0) -> 0.94334178 | H10: =IFERROR(C10/E10,0) -> 9.1594957 | I10: =Assumptions!C68 -> 16.5
B11: =Assumptions!B69 -> 0 | C11: =Assumptions!D69 -> 0 | D11: =Assumptions!E69 -> 0 | E11: =Assumptions!F69 -> 0 | G11: =IFERROR(C11/D11,0) -> 0 | H11: =IFERROR(C11/E11,0) -> 0 | I11: =Assumptions!C69 -> 0
B12: =Assumptions!B70 -> 0 | C12: =Assumptions!D70 -> 0 | D12: =Assumptions!E70 -> 0 | E12: =Assumptions!F70 -> 0 | G12: =IFERROR(C12/D12,0) -> 0 | H12: =IFERROR(C12/E12,0) -> 0 | I12: =Assumptions!C70 -> 0
B15: SUMMARY
B16: Metrics | C16: Comps | D16: Implied EV | E16: Net Debt | F16: Equity Value | G16: Shares | H16: Share Price
B17: EV / Sales
B18: Mean | C18: =AVERAGE(G$8:G$12) -> 0.6598475 | D18: =+$D$6*C18 -> 35032.624 | E18: ='Balance Sheet'!$G$48 -> 9462 | F18: =+D18-E18 -> 25570.624 | G18: =Assumptions!$C$36 -> 285.8 | H18: =+F18/G18 -> 89.470341
B19: 25 Percentile | C19: =PERCENTILE(G$8:G$12,0.25) -> 0 | D19: =+$D$6*C19 -> 0 | E19: ='Balance Sheet'!$G$48 -> 9462 | F19: =+D19-E19 -> -9462 | G19: =Assumptions!$C$36 -> 285.8 | H19: =+F19/G19 -> -33.107068
B20: 75 Percentile | C20: =PERCENTILE(G$8:G$12,0.75) -> 0.94334178 | D20: =+$D$6*C20 -> 50083.902 | E20: ='Balance Sheet'!$G$48 -> 9462 | F20: =+D20-E20 -> 40621.902 | G20: =Assumptions!$C$36 -> 285.8 | H20: =+F20/G20 -> 142.13402
B21: EV / EBITDA
B22: Mean | C22: =AVERAGE(H$8:H$12) -> 6.363566 | D22: =+$E$6*C22 -> 18759.793 | E22: ='Balance Sheet'!$G$48 -> 9462 | F22: =+D22-E22 -> 9297.7926 | G22: =Assumptions!$C$36 -> 285.8 | H22: =+F22/G22 -> 32.532514
B23: 25 Percentile | C23: =PERCENTILE(H$8:H$12,0.25) -> 0 | D23: =+$E$6*C23 -> 0 | E23: ='Balance Sheet'!$G$48 -> 9462 | F23: =+D23-E23 -> -9462 | G23: =Assumptions!$C$36 -> 285.8 | H23: =+F23/G23 -> -33.107068
B24: 75 Percentile | C24: =PERCENTILE(H$8:H$12,0.75) -> 9.1594957 | D24: =+$E$6*C24 -> 27002.193 | E24: ='Balance Sheet'!$G$48 -> 9462 | F24: =+D24-E24 -> 17540.193 | G24: =Assumptions!$C$36 -> 285.8 | H24: =+F24/G24 -> 61.372265
B25: P / E
B26: Mean | C26: =AVERAGE(I$8:I$12) -> 9.4 | D26: =+$F$6*C26 -> -6091.2 | E26: ='Balance Sheet'!$G$48 -> 9462 | F26: =+D26-E26 -> -15553.2 | G26: =Assumptions!$C$36 -> 285.8 | H26: =+F26/G26 -> -54.419874
B27: 25 Percentile | C27: =PERCENTILE(I$8:I$12,0.25) -> 0 | D27: =+$F$6*C27 -> 0 | E27: ='Balance Sheet'!$G$48 -> 9462 | F27: =+D27-E27 -> -9462 | G27: =Assumptions!$C$36 -> 285.8 | H27: =+F27/G27 -> -33.107068
B28: 75 Percentile | C28: =PERCENTILE(I$8:I$12,0.75) -> 16.5 | D28: =+$F$6*C28 -> -10692 | E28: ='Balance Sheet'!$G$48 -> 9462 | F28: =+D28-E28 -> -20154 | G28: =Assumptions!$C$36 -> 285.8 | H28: =+F28/G28 -> -70.517845
B31: Value Per Share
A32: Base | B32: Mean | C32: =+AVERAGE(H18,H22,H26) -> 22.52766
A33: Bear | B33: 25 Percentile | C33: =+AVERAGE(H19,H23,H27) -> -33.107068
A34: Bull | B34: 75 Percentile | C34: =+AVERAGE(H20,H24,H28) -> 44.329479

Sheet Internal Rate of Return
B2: Internal Rate of Return | E2: Discounted Free Cash Flow to Equity
A3: Base | B3: ="IRR - "&A3 -> IRR - Base | E3: =Assumptions!$B$132 -> Year Ending 09/31/2024, In USD Millions | F3: {=_xlfn.SEQUENCE(1,Assumptions!$C$20,(YEAR(Assumptions!$C$19)))} -> 2024 | G3: 2025 | H3: 2026 | I3: 2027 | J3: 2028
B4: ="Free Cash Flow to Equity at Year "&COUNTA(F3:O3) -> Free Cash Flow to Equity at Year 5 | C4: {=LOOKUP(2,1/($F4:$O4<>""),$F4:$O4)} -> 2060.8523 | E4: Free Cash Flow | F4: =IF(F3="","",'Discounted Cash Flow'!I15) -> 1984.5683 | G4: =IF(G3="","",'Discounted Cash Flow'!J15) -> 1775.1061 | H4: =IF(H3="","",'Discounted Cash Flow'!K15) -> 2131.4753 | I4: =IF(I3="","",'Discounted Cash Flow'!L15) -> 2733.9633 | J4: =IF(J3="","",'Discounted Cash Flow'!M15) -> 2060.8523 | K4: =IF(K3="","",'Discounted Cash Flow'!N15) | L4: =IF(L3="","",'Discounted Cash Flow'!O15) | M4: =IF(M3="","",'Discounted Cash Flow'!P15) | ... O4: =IF(O3="","",'Discounted Cash Flow'!R15)
B5: Cost of Equity | C5: =Assumptions!$C$121 -> 0.068229
B6: Perpetuity Growth Rate | C6: =Assumptions!$C$133 -> 0.01 | E6: Non-Operating (Income) Loss | F6: =IF(F3="","",'Income Statement'!H$25) -> 524.11159 | G6: =IF(G3="","",'Income Statement'!I$25) -> 509.36479 | H6: =IF(H3="","",'Income Statement'!J$25) -> 511.83324 | I6: =IF(I3="","",'Income Statement'!K$25) -> 525.46603 | J6: =IF(J3="","",'Income Statement'!L$25) -> 533.84674 | K6: =IF(K3="","",'Income Statement'!M$25) | L6: =IF(L3="","",'Income Statement'!N$25) | M6: =IF(M3="","",'Income Statement'!O$25) | ... O6: =IF(O3="","",'Income Statement'!Q$25)
B7: ="Terminal value at Year "&COUNTA(F3:O3) -> Terminal value at Year 5 | C7: =(C4*(1+C5))/(C5-C6) -> 37806.973
E8: Free Cash Flow to Equity | F8: =IF(F3="","",F4-F6) -> 1460.4567 | G8: =IF(G3="","",G4-G6) -> 1265.7413 | H8: =IF(H3="","",H4-H6) -> 1619.6421 | I8: =IF(I3="","",I4-I6) -> 2208.4973 | J8: =IF(J3="","",J4-J6) -> 1527.0056 | K8: =IF(K3="","",K4-K6) | L8: =IF(L3="","",L4-L6) | M8: =IF(M3="","",M4-M6) | ... O8: =IF(O3="","",O4-O6)
B9: Discounted Terminal Value | C9: =C7/(1+C5)^COUNTA($F3:$O3) -> 27180.04
B10: PV of Free Cash Flow to Equity | C10: =SUM(F12:O12) -> 6598.9308 | E10: Discount Factor | F10: =IF(F3="","",1/((1+$C5)^COUNTA($F3:F3))) -> 0.93612886 | G10: =IF(G3="","",1/((1+$C5)^COUNTA($F3:G3))) -> 0.87633725 | H10: =IF(H3="","",1/((1+$C5)^COUNTA($F3:H3))) -> 0.82036459 | I10: =IF(I3="","",1/((1+$C5)^COUNTA($F3:I3))) -> 0.76796697 | J10: =IF(J3="","",1/((1+$C5)^COUNTA($F3:J3))) -> 0.71891605 | K10: =IF(K3="","",1/((1+$C5)^COUNTA($F3:K3))) | L10: =IF(L3="","",1/((1+$C5)^COUNTA($F3:L3))) | M10: =IF(M3="","",1/((1+$C5)^COUNTA($F3:M3))) | ... O10: =IF(O3="","",1/((1+$C5)^COUNTA($F3:O3)))
B11: Equity Value | C11: =C9+C10 -> 33778.971
E12: Discounted Free Cash Flow to Equity | F12: =IF(F3="","",F8*F10) -> 1367.1756 | G12: =IF(G3="","",G8*G10) -> 1109.2163 | H12: =IF(H3="","",H8*H10) -> 1328.697 | I12: =IF(I3="","",I8*I10) -> 1696.053 | J12: =IF(J3="","",J8*J10) -> 1097.7888 | K12: =IF(K3="","",K8*K10) | L12: =IF(L3="","",L8*L10) | M12: =IF(M3="","",M8*M10) | ... O12: =IF(O3="","",O8*O10)
B13: Net Debt | C13: =+'Balance Sheet'!$G$48 -> 9462
B14: Minority Interest | C14: =+'Balance Sheet'!$G$37 -> 122
B15: Enterprise Value | C15: =C11-C13-C14 -> 24194.971
B17: Shares Outstanding | C17: =+Assumptions!$C$36 -> 285.8
B18: Value Per Share | C18: =C15/C17 -> 84.657
A21: Bear | B21: ="IRR - "&A21 -> IRR - Bear | E21: =Assumptions!$B$132 -> Year Ending 09/31/2024, In USD Millions | F21: {=_xlfn.SEQUENCE(1,Assumptions!$C$20,(YEAR(Assumptions!$C$19)))} -> 2024 | G21: 2025 | H21: 2026 | I21: 2027 | J21: 2028
B22: ="Free Cash Flow to Equity at Year "&COUNTA(F21:O21) -> Free Cash Flow to Equity at Year 5 | C22: {=LOOKUP(2,1/($F22:$O22<>""),$F22:$O22)} -> 2047.9268 | E22: Free Cash Flow | F22: =IF(F21="","",'Discounted Cash Flow'!I33) -> 1451.3109 | G22: =IF(G21="","",'Discounted Cash Flow'!J33) -> 1812.1753 | H22: =IF(H21="","",'Discounted Cash Flow'!K33) -> 2151.8765 | I22: =IF(I21="","",'Discounted Cash Flow'!L33) -> 2737.7001 | J22: =IF(J21="","",'Discounted Cash Flow'!M33) -> 2047.9268 | K22: =IF(K21="","",'Discounted Cash Flow'!N33) | L22: =IF(L21="","",'Discounted Cash Flow'!O33) | M22: =IF(M21="","",'Discounted Cash Flow'!P33) | ... O22: =IF(O21="","",'Discounted Cash Flow'!R33)
B23: Cost of Equity | C23: =Assumptions!$C$121 -> 0.068229
B24: Perpetuity Growth Rate | C24: =Assumptions!$C$133 -> 0.01 | E24: Non-Operating (Income) Loss | F24: =IF(F21="","",'IS Bear'!H$25) -> 520.87022 | G24: =IF(G21="","",'IS Bear'!I$25) -> 502.88206 | H24: =IF(H21="","",'IS Bear'!J$25) -> 502.10882 | I24: =IF(I21="","",'IS Bear'!K$25) -> 512.49927 | J24: =IF(J21="","",'IS Bear'!L$25) -> 517.63667 | K24: =IF(K21="","",'Income Statement'!M$25) | L24: =IF(L21="","",'Income Statement'!N$25) | M24: =IF(M21="","",'Income Statement'!O$25) | N24: =IF(N21="","",'Income Statement'!P$25) | O24: =IF(O21="","",'Income Statement'!Q$25)
B25: ="Terminal value at Year "&COUNTA(F21:O21) -> Terminal value at Year 5 | C25: =(C22*(1+C23))/(C23-C24) -> 37569.851
E26: Free Cash Flow to Equity | F26: =IF(F21="","",F22-F24) -> 930.44065 | G26: =IF(G21="","",G22-G24) -> 1309.2932 | H26: =IF(H21="","",H22-H24) -> 1649.7677 | I26: =IF(I21="","",I22-I24) -> 2225.2009 | J26: =IF(J21="","",J22-J24) -> 1530.2902 | K26: =IF(K21="","",K22-K24) | L26: =IF(L21="","",L22-L24) | M26: =IF(M21="","",M22-M24) | ... O26: =IF(O21="","",O22-O24)
B27: Discounted Terminal Value | C27: =C25/(1+C23)^COUNTA($F21:$O21) -> 27009.569
B28: PV of Free Cash Flow to Equity | C28: =SUM(F30:O30) -> 6180.8367 | E28: Discount Factor | F28: =IF(F21="","",1/((1+$C23)^COUNTA($F21:F21))) -> 0.93612886 | G28: =IF(G21="","",1/((1+$C23)^COUNTA($F21:G21))) -> 0.87633725 | H28: =IF(H21="","",1/((1+$C23)^COUNTA($F21:H21))) -> 0.82036459 | I28: =IF(I21="","",1/((1+$C23)^COUNTA($F21:I21))) -> 0.76796697 | J28: =IF(J21="","",1/((1+$C23)^COUNTA($F21:J21))) -> 0.71891605 | K28: =IF(K21="","",1/((1+$C23)^COUNTA($F21:K21))) | L28: =IF(L21="","",1/((1+$C23)^COUNTA($F21:L21))) | M28: =IF(M21="","",1/((1+$C23)^COUNTA($F21:M21))) | ... O28: =IF(O21="","",1/((1+$C23)^COUNTA($F21:O21)))
B29: Equity Value | C29: =C27+C28 -> 33190.406
E30: Discounted Free Cash Flow to Equity | F30: =IF(F21="","",F26*F28) -> 871.01235 | G30: =IF(G21="","",G26*G28) -> 1147.3824 | H30: =IF(H21="","",H26*H28) -> 1353.411 | I30: =IF(I21="","",I26*I28) -> 1708.8808 | J30: =IF(J21="","",J26*J28) -> 1100.1502 | K30: =IF(K21="","",K26*K28) | L30: =IF(L21="","",L26*L28) | M30: =IF(M21="","",M26*M28) | ... O30: =IF(O21="","",O26*O28)
B31: Net Debt | C31: =+'Balance Sheet'!$G$48 -> 9462
B32: Minority Interest | C32: =+'Balance Sheet'!$G$37 -> 122
B33: Enterprise Value | C33: =C29-C31-C32 -> 23606.406
B35: Shares Outstanding | C35: =+Assumptions!$C$36 -> 285.8
B36: Value Per Share | C36: =C33/C35 -> 82.59764
A39: Bull | B39: ="IRR - "&A39 -> IRR - Bull | E39: =Assumptions!$B$132 -> Year Ending 09/31/2024, In USD Millions | F39: {=_xlfn.SEQUENCE(1,Assumptions!$C$20,(YEAR(Assumptions!$C$19)))} -> 2024 | G39: 2025 | H39: 2026 | I39: 2027 | J39: 2028
B40: ="Free Cash Flow to Equity at Year "&COUNTA(F39:O39) -> Free Cash Flow to Equity at Year 5 | C40: {=LOOKUP(2,1/($F40:$O40<>""),$F40:$O40)} -> 2068.8657 | E40: Free Cash Flow | F40: =IF(F39="","",'Discounted Cash Flow'!I51) -> 1343.8257 | G40: =IF(G39="","",'Discounted Cash Flow'!J51) -> 1735.8872 | H40: =IF(H39="","",'Discounted Cash Flow'!K51) -> 2107.3772 | I40: =IF(I39="","",'Discounted Cash Flow'!L51) -> 2725.6026 | J40: =IF(J39="","",'Discounted Cash Flow'!M51) -> 2068.8657 | K40: =IF(K39="","",'Discounted Cash Flow'!N51) | L40: =IF(L39="","",'Discounted Cash Flow'!O51) | M40: =IF(M39="","",'Discounted Cash Flow'!P51) | ... O40: =IF(O39="","",'Discounted Cash Flow'!R51)
B41: Cost of Equity | C41: =Assumptions!$C$121 -> 0.068229
B42: Perpetuity Growth Rate | C42: =Assumptions!$C$133 -> 0.01 | E42: Non-Operating (Income) Loss | F42: =IF(F39="","",'IS Bull'!H$25) -> 527.35296 | G42: =IF(G39="","",'IS Bull'!I$25) -> 515.97718 | H42: =IF(H39="","",'IS Bull'!J$25) -> 521.95052 | I42: =IF(I39="","",'IS Bull'!K$25) -> 539.22641 | J42: =IF(J39="","",'IS Bull'!L$25) -> 551.39291 | K42: =IF(K39="","",'IS Bull'!M$25) | L42: =IF(L39="","",'IS Bull'!N$25) | M42: =IF(M39="","",'IS Bull'!O$25) | ... O42: =IF(O39="","",'IS Bull'!Q$25)
B43: ="Terminal value at Year "&COUNTA(F39:O39) -> Terminal value at Year 5 | C43: =(C40*(1+C41))/(C41-C42) -> 37953.981
E44: Free Cash Flow to Equity | F44: =IF(F39="","",F40-F42) -> 816.4727 | G44: =IF(G39="","",G40-G42) -> 1219.91 | H44: =IF(H39="","",H40-H42) -> 1585.4267 | I44: =IF(I39="","",I40-I42) -> 2186.3762 | J44: =IF(J39="","",J40-J42) -> 1517.4728 | K44: =IF(K39="","",K40-K42) | L44: =IF(L39="","",L40-L42) | M44: =IF(M39="","",M40-M42) | ... O44: =IF(O39="","",O40-O42)
B45: Discounted Terminal Value | C45: =C43/(1+C41)^COUNTA($F39:$O39) -> 27285.726
B46: PV of Free Cash Flow to Equity | C46: =SUM(F48:O48) -> 5904.0045 | E46: Discount Factor | F46: =IF(F39="","",1/((1+$C41)^COUNTA($F39:F39))) -> 0.93612886 | G46: =IF(G39="","",1/((1+$C41)^COUNTA($F39:G39))) -> 0.87633725 | H46: =IF(H39="","",1/((1+$C41)^COUNTA($F39:H39))) -> 0.82036459 | I46: =IF(I39="","",1/((1+$C41)^COUNTA($F39:I39))) -> 0.76796697 | J46: =IF(J39="","",1/((1+$C41)^COUNTA($F39:J39))) -> 0.71891605 | K46: =IF(K39="","",1/((1+$C41)^COUNTA($F39:K39))) | L46: =IF(L39="","",1/((1+$C41)^COUNTA($F39:L39))) | M46: =IF(M39="","",1/((1+$C41)^COUNTA($F39:M39))) | ... O46: =IF(O39="","",1/((1+$C41)^COUNTA($F39:O39)))
B47: Equity Value | C47: =C45+C46 -> 33189.731
...

Sheet Dividend Discount
B2: Dividend Discount Model - 2 Stage
A3: Base | B3: ="DDM - "&A3&" - "&Assumptions!$C$54 -> DDM - Base - CAGR | C3: {=_xlfn.SEQUENCE(1,6,(YEAR(Assumptions!$C$19)-1))} -> 2023 | D3: 2024 | E3: 2025 | F3: 2026 | G3: 2027 | H3: 2028
C4: 0 | D4: 1 | E4: 2 | F4: 3 | G4: 4 | H4: 5
B5: Annual Dividends Per Share | C5: =Assumptions!$C$56 -> 1.93 | D5: =C5*(1+$C9) -> 2.017823 | E5: =D5*(1+$C9) -> 2.1096424 | F5: =E5*(1+$C9) -> 2.2056399 | G5: =F5*(1+$C9) -> 2.3060057 | H5: =G5*(1+$C9) -> 2.4109385
B6: Cost of Equity | C6: =Assumptions!$C$57 -> 0.068229
B7: Present Value of Dividend | C7: =C5/(1+$C6)^C4 -> 1.93 | D7: =D5/(1+$C6)^D4 -> 1.8889424 | E7: =E5/(1+$C6)^E4 -> 1.8487582 | F7: =F5/(1+$C6)^F4 -> 1.8094289 | G7: =G5/(1+$C6)^G4 -> 1.7709362 | H7: =H5/(1+$C6)^H4 -> 1.7332624
B9: Dividend Growth Rate Stage 1 | C9: =IF(Assumptions!$C$54="CAGR",Assumptions!$C$46,Assumptions!$C$50) -> 0.04550416
B10: Dividend Growth Rate Stage 2 | C10: =Assumptions!$C$133 -> 0.01
B12: Sum of Stage 1 Dividends | C12: =SUM(D7:H7) -> 9.051328
B13: Year 5 Dividend * (1 + Stage 2 Growth Rate) | C13: =H5*(1+$C10) -> 2.4350479
B14: Stage 2 Terminal Value | C14: =C13/(C6-C10) -> 41.818474
B15: PV of Stage 2 Terminal Value | C15: =C14/(1+C6)^H4 -> 30.063972
B16: Value Per Share | C16: =SUM(C12,C15) -> 39.1153
A19: Bear | B19: ="DDM - "&A19&" - "&Assumptions!$C$54 -> DDM - Bear - CAGR | C19: {=_xlfn.SEQUENCE(1,6,(YEAR(Assumptions!$C$19)-1))} -> 2023 | D19: 2024 | E19: 2025 | F19: 2026 | G19: 2027 | H19: 2028
C20: 0 | D20: 1 | E20: 2 | F20: 3 | G20: 4 | H20: 5
B21: Annual Dividends Per Share | C21: =Assumptions!$C$56 -> 1.93 | D21: =C21*(1+$C25) -> 1.998523 | E21: =D21*(1+$C25) -> 2.0694789 | F21: =E21*(1+$C25) -> 2.142954 | G21: =F21*(1+$C25) -> 2.2190378 | H21: =G21*(1+$C25) -> 2.2978229
B22: Cost of Equity | C22: =Assumptions!$C$57 -> 0.068229 | D22: =C22 -> 0.068229 | E22: =D22 -> 0.068229 | F22: =E22 -> 0.068229 | G22: =F22 -> 0.068229 | H22: =G22 -> 0.068229
B23: Present Value of Dividend | C23: =C21/(1+C22)^C20 -> 1.93 | D23: =D21/(1+D22)^D20 -> 1.8708751 | E23: =E21/(1+E22)^E20 -> 1.8135615 | F23: =F21/(1+F22)^F20 -> 1.7580036 | G23: =G21/(1+G22)^G20 -> 1.7041477 | H23: =H21/(1+H22)^H20 -> 1.6519417
B25: Dividend Growth Rate Stage 1 | C25: =IF(Assumptions!$C$54="CAGR",Assumptions!$C$47,Assumptions!$C$51) -> 0.03550416
B26: Dividend Growth Rate Stage 2 | C26: =Assumptions!$C$133 -> 0.01
B28: Sum of Stage 1 Dividends | C28: =SUM(D23:H23) -> 8.7985296
B29: Year 5 Dividend * (1 + Stage 2 Growth Rate) | C29: =H21*(1+$C26) -> 2.3208011
B30: Stage 2 Terminal Value | C30: =C29/(C22-C26) -> 39.856448
B31: PV of Stage 2 Terminal Value | C31: =C30/(1+C22)^H20 -> 28.65344
B32: Value Per Share | C32: =SUM(C28,C31) -> 37.45197
A35: Bull | B35: ="DDM - "&A35&" - "&Assumptions!$C$54 -> DDM - Bull - CAGR | C35: {=_xlfn.SEQUENCE(1,6,(YEAR(Assumptions!$C$19)-1))} -> 2023 | D35: 2024 | E35: 2025 | F35: 2026 | G35: 2027 | H35: 2028
C36: 0 | D36: 1 | E36: 2 | F36: 3 | G36: 4 | H36: 5
B37: Annual Dividends Per Share | C37: =Assumptions!$C$56 -> 1.93 | D37: =C37*(1+$C41) -> 2.037123 | E37: =D37*(1+$C41) -> 2.1501918 | F37: =E37*(1+$C41) -> 2.2695364 | G37: =F37*(1+$C41) -> 2.3955051 | H37: =G37*(1+$C41) -> 2.5284656
B38: Cost of Equity | C38: =Assumptions!$C$57 -> 0.068229 | D38: =C38 -> 0.068229 | E38: =D38 -> 0.068229 | F38: =E38 -> 0.068229 | G38: =F38 -> 0.068229 | H38: =G38 -> 0.068229
B39: Present Value of Dividend | C39: =C37/(1+C38)^C36 -> 1.93 | D39: =D37/(1+D38)^D36 -> 1.9070097 | E39: =E37/(1+E38)^E36 -> 1.8842932 | F39: =F37/(1+F38)^F36 -> 1.8618473 | G39: =G37/(1+G38)^G36 -> 1.8396688 | H39: =H37/(1+H38)^H36 -> 1.8177545
B41: Dividend Growth Rate Stage 1 | C41: =IF(Assumptions!$C$54="CAGR",Assumptions!$C$48,Assumptions!$C$52) -> 0.05550416
B42: Dividend Growth Rate Stage 2 | C42: =Assumptions!$C$133 -> 0.01
B44: Sum of Stage 1 Dividends | C44: =SUM(D39:H39) -> 9.3105735
B45: Year 5 Dividend * (1 + Stage 2 Growth Rate) | C45: =H37*(1+$C42) -> 2.5537503
B46: Stage 2 Terminal Value | C46: =C45/(C38-C42) -> 43.857018
B47: PV of Stage 2 Terminal Value | C47: =C46/(1+C38)^H36 -> 31.529514
B48: Value Per Share | C48: =SUM(C44,C47) -> 40.840088
B51: Dividend Discount Model Summary
B52: Scenarios
A53: Base | B53: =B3 -> DDM - Base - CAGR | C53: =C16 -> 39.1153
...

Sheet Income Statement
B2: Income Statement - Base
B3: =Assumptions!$B$132 -> Year Ending 09/31/2024, In USD Millions | C3: {=_xlfn.SEQUENCE(1,5+Assumptions!$C$20,(YEAR('Valuation Summary'!$C$4)-5))} -> 2019 | D3: 2020 | E3: 2021 | F3: 2022 | G3: 2023 | H3: 2024 | I3: 2025 | J3: 2026 | K3: 2027 | L3: 2028
B4: =Assumptions!B136 -> Revenue | C4: =Assumptions!D136 -> 42405 | D4: =Assumptions!E136 -> 43185 | E4: =Assumptions!F136 -> 47049 | F4: =Assumptions!G136 -> 53282 | G4: =Assumptions!H136 -> 52881 | H4: =IF(H3="",0,G4*(1+H6)) -> 53409.81 | I4: =IF(I3="",0,H4*(1+I6)) -> 53943.908 | J4: =IF(J3="",0,I4*(1+J6)) -> 54483.347 | K4: =IF(K3="",0,J4*(1+K6)) -> 55028.181 | L4: =IF(L3="",0,K4*(1+L6)) -> 55578.462 | M4: =IF(M3="",0,L4*(1+M6)) -> 0 | N4: =IF(N3="",0,M4*(1+N6)) -> 0 | O4: =IF(O3="",0,N4*(1+O6)) -> 0 | ... Q4: =IF(Q3="",0,P4*(1+Q6)) -> 0
B5: ="% of "&$B$4 -> % of Revenue | C5: =IFERROR(C4/C$4,0) -> 1 | D5: =D4/D$4 -> 1 | E5: =E4/E$4 -> 1 | F5: =F4/F$4 -> 1 | G5: =G4/G$4 -> 1 | H5: =IFERROR(H4/H$4,0) -> 1 | I5: =IFERROR(I4/I$4,0) -> 1 | J5: =IFERROR(J4/J$4,0) -> 1 | K5: =IFERROR(K4/K$4,0) -> 1 | L5: =IFERROR(L4/L$4,0) -> 1 | M5: =IFERROR(M4/M$4,0) -> 0 | N5: =IFERROR(N4/N$4,0) -> 0 | O5: =IFERROR(O4/O$4,0) -> 0 | ... Q5: =IFERROR(Q4/Q$4,0) -> 0
B6: Year over Year Growth % | D6: =D4/C4-1 -> 0.018394057 | E6: =E4/D4-1 -> 0.089475512 | F6: =F4/E4-1 -> 0.1324789 | G6: =G4/F4-1 -> -0.0075259938 | H6: =Assumptions!I$137 -> 0.01 | I6: =Assumptions!J$137 -> 0.01 | J6: =Assumptions!K$137 -> 0.01 | K6: =Assumptions!L$137 -> 0.01 | L6: =Assumptions!M$137 -> 0.01 | M6: =Assumptions!N$137 -> 0 | N6: =Assumptions!O$137 -> 0 | O6: =Assumptions!P$137 -> 0 | ... Q6: =Assumptions!R$137 -> 0
B8: =Assumptions!B142 -> Cost of Revenue ~ Cost of Goods Sold | C8: =Assumptions!D142 -> 37383 | D8: =Assumptions!E142 -> 37801 | E8: =Assumptions!F142 -> 40523 | F8: =Assumptions!G142 -> 46614 | G8: =Assumptions!H142 -> 50250 | H8: =H$4*H9 -> 47463.082 | I8: =I$4*I9 -> 47937.713 | J8: =J$4*J9 -> 48417.09 | K8: =K$4*K9 -> 48901.261 | L8: =L$4*L9 -> 49390.273 | M8: =M$4*M9 -> 0 | N8: =N$4*N9 -> 0 | O8: =O$4*O9 -> 0 | ... Q8: =Q$4*Q9 -> 0
B9: ="% of "&$B$4 -> % of Revenue | C9: =IFERROR(C8/C$4,0) -> 0.88157057 | D9: =D8/D$4 -> 0.87532708 | E9: =E8/E$4 -> 0.86129355 | F9: =F8/F$4 -> 0.87485455 | G9: =G8/G$4 -> 0.95024678 | H9: =Assumptions!I$143 -> 0.8886585 | I9: =Assumptions!J$143 -> 0.8886585 | J9: =Assumptions!K$143 -> 0.8886585 | K9: =Assumptions!L$143 -> 0.8886585 | L9: =Assumptions!M$143 -> 0.8886585 | M9: =Assumptions!N$143 -> 0 | N9: =Assumptions!O$143 -> 0 | O9: =Assumptions!P$143 -> 0 | ... Q9: =Assumptions!R$143 -> 0
B10: Year over Year Growth % | D10: =D8/C8-1 -> 0.011181553 | E10: =E8/D8-1 -> 0.072008677 | F10: =F8/E8-1 -> 0.1503097 | G10: =G8/F8-1 -> 0.078002317 | H10: =IF(H$3="",0,H8/G8-1) -> -0.055461057 | I10: =IF(I$3="",0,I8/H8-1) -> 0.01 | J10: =IF(J$3="",0,J8/I8-1) -> 0.01 | K10: =IF(K$3="",0,K8/J8-1) -> 0.01 | L10: =IF(L$3="",0,L8/K8-1) -> 0.01 | M10: =IF(M$3="",0,M8/L8-1) -> 0 | N10: =IF(N$3="",0,N8/M8-1) -> 0 | O10: =IF(O$3="",0,O8/N8-1) -> 0 | ... Q10: =IF(Q$3="",0,Q8/P8-1) -> 0
B12: Gross Profit | C12: =C4-C8 -> 5022 | D12: =D4-D8 -> 5384 | E12: =E4-E8 -> 6526 | F12: =F4-F8 -> 6668 | G12: =G4-G8 -> 2631 | H12: =H4-H8 -> 5946.7281 | I12: =I4-I8 -> 6006.1954 | J12: =J4-J8 -> 6066.2573 | ... Q12: =Q4-Q8 -> 0
B13: ="% of "&$B$4 -> % of Revenue | C13: =IFERROR(C12/C$4,0) -> 0.11842943 | D13: =D12/D$4 -> 0.12467292 | E13: =E12/E$4 -> 0.13870645 | F13: =F12/F$4 -> 0.12514545 | G13: =G12/G$4 -> 0.049753219 | H13: =IFERROR(H12/H$4,0) -> 0.1113415 | I13: =IFERROR(I12/I$4,0) -> 0.1113415 | J13: =IFERROR(J12/J$4,0) -> 0.1113415 | K13: =IFERROR(K12/K$4,0) -> 0.1113415 | L13: =IFERROR(L12/L$4,0) -> 0.1113415 | M13: =IFERROR(M12/M$4,0) -> 0 | N13: =IFERROR(N12/N$4,0) -> 0 | O13: =IFERROR(O12/O$4,0) -> 0 | ... Q13: =IFERROR(Q12/Q$4,0) -> 0
B14: Year over Year Growth % | D14: =D12/C12-1 -> 0.072082836 | E14: =E12/D12-1 -> 0.21210996 | F14: =F12/E12-1 -> 0.021759117 | G14: =G12/F12-1 -> -0.60542891 | H14: =IF(H3="",0,H12/G12-1) -> 1.2602539 | I14: =IF(I3="",0,I12/H12-1) -> 0.01 | J14: =IF(J3="",0,J12/I12-1) -> 0.01 | K14: =IF(K3="",0,K12/J12-1) -> 0.01 | L14: =IF(L3="",0,L12/K12-1) -> 0.01 | M14: =IF(M3="",0,M12/L12-1) -> 0 | N14: =IF(N3="",0,N12/M12-1) -> 0 | O14: =IF(O3="",0,O12/N12-1) -> 0 | ... Q14: =IF(Q3="",0,Q12/P12-1) -> 0
B16: =Assumptions!B146 -> Other Operating Income | C16: =Assumptions!D146 -> 0 | D16: =Assumptions!E146 -> 0 | E16: =Assumptions!F146 -> 0 | F16: =Assumptions!G146 -> 0 | G16: =Assumptions!H146 -> 0 | H16: =H$4*H17 -> 0 | I16: =I$4*I17 -> 0 | J16: =J$4*J17 -> 0 | K16: =K$4*K17 -> 0 | L16: =L$4*L17 -> 0 | M16: =M$4*M17 -> 0 | N16: =N$4*N17 -> 0 | O16: =O$4*O17 -> 0 | ... Q16: =Q$4*Q17 -> 0
B17: ="% of "&$B$4 -> % of Revenue | C17: =IFERROR(C16/C$4,0) -> 0 | D17: =D16/D$4 -> 0 | E17: =E16/E$4 -> 0 | F17: =F16/F$4 -> 0 | G17: =G16/G$4 -> 0 | H17: =Assumptions!I$147 -> 0 | I17: =Assumptions!J$147 -> 0 | J17: =Assumptions!K$147 -> 0 | K17: =Assumptions!L$147 -> 0 | L17: =Assumptions!M$147 -> 0 | M17: =Assumptions!N$147 -> 0 | N17: =Assumptions!O$147 -> 0 | O17: =Assumptions!P$147 -> 0 | ... Q17: =Assumptions!R$147 -> 0
B19: =Assumptions!B150 -> Operating Expenses | C19: =Assumptions!D150 -> 1959 | D19: =Assumptions!E150 -> 2481 | E19: =Assumptions!F150 -> 2278 | F19: =Assumptions!G150 -> 2306 | G19: =Assumptions!H150 -> 1737 | H19: =H$4*H20 -> 2437.5381 | I19: =I$4*I20 -> 2461.9135 | J19: =J$4*J20 -> 2486.5326 | K19: =K$4*K20 -> 2511.398 | L19: =L$4*L20 -> 2536.5119 | M19: =M$4*M20 -> 0 | N19: =N$4*N20 -> 0 | O19: =O$4*O20 -> 0 | ... Q19: =Q$4*Q20 -> 0
B20: ="% of "&$B$4 -> % of Revenue | C20: =IFERROR(C19/C$4,0) -> 0.046197382 | D20: =D19/D$4 -> 0.057450504 | E20: =E19/E$4 -> 0.048417607 | F20: =F19/F$4 -> 0.043279156 | G20: =G19/G$4 -> 0.032847336 | H20: =Assumptions!I$151 -> 0.045638397 | I20: =Assumptions!J$151 -> 0.045638397 | J20: =Assumptions!K$151 -> 0.045638397 | K20: =Assumptions!L$151 -> 0.045638397 | L20: =Assumptions!M$151 -> 0.045638397 | M20: =Assumptions!N$151 -> 0 | N20: =Assumptions!O$151 -> 0 | O20: =Assumptions!P$151 -> 0 | ... Q20: =Assumptions!R$151 -> 0
B22: Operating Income (Loss) ~ EBIT | C22: =C12+C16-C19 -> 3063 | D22: =D12+D16-D19 -> 2903 | E22: =E12+E16-E19 -> 4248 | F22: =F12+F16-F19 -> 4362 | G22: =G12+G16-G19 -> 894 | H22: =H12+H16-H19 -> 3509.19 | I22: =I12+I16-I19 -> 3544.2819 | J22: =J12+J16-J19 -> 3579.7247 | ... Q22: =Q12+Q16-Q19 -> 0
B23: ="% of "&$B$4 -> % of Revenue | C23: =IFERROR(C22/C$4,0) -> 0.072232048 | D23: =D22/D$4 -> 0.067222415 | E23: =E22/E$4 -> 0.090288848 | F23: =F22/F$4 -> 0.081866296 | G23: =G22/G$4 -> 0.016905883 | H23: =IFERROR(H22/H$4,0) -> 0.065703098 | I23: =IFERROR(I22/I$4,0) -> 0.065703098 | J23: =IFERROR(J22/J$4,0) -> 0.065703098 | K23: =IFERROR(K22/K$4,0) -> 0.065703098 | L23: =IFERROR(L22/L$4,0) -> 0.065703098 | M23: =IFERROR(M22/M$4,0) -> 0 | N23: =IFERROR(N22/N$4,0) -> 0 | O23: =IFERROR(O22/O$4,0) -> 0 | ... Q23: =IFERROR(Q22/Q$4,0) -> 0
B25: =Assumptions!B154 -> Non-Operating (Income) Loss | C25: =Assumptions!D154 -> 632 | D25: =Assumptions!E154 -> 239 | E25: =Assumptions!F154 -> 207 | F25: =Assumptions!G154 -> 213 | G25: =Assumptions!H154 -> 1572 | H25: =+Assumptions!I$154+H4*Assumptions!$I$167+H4*Assumptions!I$169 -> 524.11159 | I25: =+Assumptions!J$154+I4*Assumptions!$I$167+I4*Assumptions!J$169 -> 509.36479 | J25: =+Assumptions!K$154+J4*Assumptions!$I$167+J4*Assumptions!K$169 -> 511.83324 | K25: =+Assumptions!L$154+K4*Assumptions!$I$167+K4*Assumptions!L$169 -> 525.46603 | L25: =+Assumptions!M$154+L4*Assumptions!$I$167+L4*Assumptions!M$169 -> 533.84674 | M25: =+Assumptions!N$154+M4*Assumptions!$I$167+M4*Assumptions!N$169 -> 0 | N25: =+Assumptions!O$154+N4*Assumptions!$I$167+N4*Assumptions!O$169 -> 0 | O25: =+Assumptions!P$154+O4*Assumptions!$I$167+O4*Assumptions!P$169 -> 0 | ... Q25: =+Assumptions!R$154+Q4*Assumptions!$I$167+Q4*Assumptions!R$169 -> 0
B26: ="% of "&$B$4 -> % of Revenue | C26: =IFERROR(C25/C$4,0) -> 0.014903903 | D26: =D25/D$4 -> 0.005534329 | E26: =E25/E$4 -> 0.0043996684 | F26: =F25/F$4 -> 0.0039975977 | G26: =G25/G$4 -> 0.029727123 | H26: =IFERROR(H25/H$4,0) -> 0.0098130211 | I26: =IFERROR(I25/I$4,0) -> 0.0094424896 | J26: =IFERROR(J25/J$4,0) -> 0.0093943061 | K26: =IFERROR(K25/K$4,0) -> 0.0095490352 | L26: =IFERROR(L25/L$4,0) -> 0.0096052809 | M26: =IFERROR(M25/M$4,0) -> 0 | N26: =IFERROR(N25/N$4,0) -> 0 | O26: =IFERROR(O25/O$4,0) -> 0 | ... Q26: =IFERROR(Q25/Q$4,0) -> 0
B28: Pretax Income (Loss), GAAP ~ EBT | C28: =C22-C25 -> 2431 | D28: =D22-D25 -> 2664 | E28: =E22-E25 -> 4041 | F28: =F22-F25 -> 4149 | G28: =G22-G25 -> -678 | H28: =H22-H25 -> 2985.0784 | I28: =I22-I25 -> 3034.9171 | J28: =J22-J25 -> 3067.8915 | ... Q28: =Q22-Q25 -> 0
B29: ="% of "&$B$4 -> % of Revenue | C29: =IFERROR(C28/C$4,0) -> 0.057328145 | D29: =D28/D$4 -> 0.061688086 | E29: =E28/E$4 -> 0.085889179 | F29: =F28/F$4 -> 0.077868699 | G29: =G28/G$4 -> -0.01282124 | H29: =IFERROR(H28/H$4,0) -> 0.055890077 | I29: =IFERROR(I28/I$4,0) -> 0.056260608 | J29: =IFERROR(J28/J$4,0) -> 0.056308792 | K29: =IFERROR(K28/K$4,0) -> 0.056154063 | L29: =IFERROR(L28/L$4,0) -> 0.056097817 | M29: =IFERROR(M28/M$4,0) -> 0 | N29: =IFERROR(N28/N$4,0) -> 0 | O29: =IFERROR(O28/O$4,0) -> 0 | ... Q29: =IFERROR(Q28/Q$4,0) -> 0
B31: =Assumptions!B172 -> Income Tax Expense (Benefit) | C31: =Assumptions!D172 -> 396 | D31: =Assumptions!E172 -> 593 | E31: =Assumptions!F172 -> 981 | F31: =Assumptions!G172 -> 900 | G31: =Assumptions!H172 -> -29 | H31: =H28*Assumptions!I174 -> 626.86646 | I31: =I28*Assumptions!J174 -> 637.33259 | J31: =J28*Assumptions!K174 -> 644.25721 | K31: =K28*Assumptions!L174 -> 648.91174 | L31: =L28*Assumptions!M174 -> 654.74439 | M31: =M28*Assumptions!N174 -> 0 | N31: =N28*Assumptions!O174 -> 0 | O31: =O28*Assumptions!P174 -> 0 | ... Q31: =Q28*Assumptions!R174 -> 0
B32: ="% of "&$B$4 -> % of Revenue | C32: =IFERROR(C31/C$4,0) -> 0.0093385214 | D32: =D31/D$4 -> 0.01373162 | E32: =E31/E$4 -> 0.020850603 | F32: =F31/F$4 -> 0.016891258 | G32: =G31/G$4 -> -0.00054840113 | H32: =IFERROR(H31/H$4,0) -> 0.011736916 | I32: =IFERROR(I31/I$4,0) -> 0.011814728 | J32: =IFERROR(J31/J$4,0) -> 0.011824846 | K32: =IFERROR(K31/K$4,0) -> 0.011792353 | L32: =IFERROR(L31/L$4,0) -> 0.011780542 | M32: =IFERROR(M31/M$4,0) -> 0 | N32: =IFERROR(N31/N$4,0) -> 0 | O32: =IFERROR(O31/O$4,0) -> 0 | ... XFD32: =IFERROR(XFD31/XFD$4,0) -> 0
B34: =Assumptions!B177 -> Miscellaneous After Tax Expenditures | C34: =Assumptions!D177 -> 13 | D34: =Assumptions!E177 -> 10 | E34: =Assumptions!F177 -> 13 | F34: =Assumptions!G177 -> 11 | G34: =Assumptions!H177 -> -1 | H34: =H$4*H35 -> 10.703064 | I34: =I$4*I35 -> 10.810095 | J34: =J$4*J35 -> 10.918196 | K34: =K$4*K35 -> 11.027378 | L34: =L$4*L35 -> 11.137652 | M34: =M$4*M35 -> 0 | N34: =N$4*N35 -> 0 | O34: =O$4*O35 -> 0 | ... Q34: =Q$4*Q35 -> 0
B35: ="% of "&$B$4 -> % of Revenue | C35: =IFERROR(C34/C$4,0) -> 0.00030656762 | D35: =D34/D$4 -> 0.00023156188 | E35: =E34/E$4 -> 0.00027630768 | F35: =F34/F$4 -> 0.00020644871 | G35: =G34/G$4 -> -1.8910384e-05 | H35: =Assumptions!I178 -> 0.0002003951 | I35: =Assumptions!J178 -> 0.0002003951 | J35: =Assumptions!K178 -> 0.0002003951 | K35: =Assumptions!L178 -> 0.0002003951 | L35: =Assumptions!M178 -> 0.0002003951 | M35: =Assumptions!N178 -> 0 | N35: =Assumptions!O178 -> 0 | O35: =Assumptions!P178 -> 0 | ... Q35: =Assumptions!R178 -> 0
B37: Net Income (Loss), GAAP | C37: =C28-C31-C34 -> 2022 | D37: =D28-D31-D34 -> 2061 | E37: =E28-E31-E34 -> 3047 | F37: =F28-F31-F34 -> 3238 | G37: =G28-G31-G34 -> -648 | H37: =H28-H31-H34 -> 2347.5089 | I37: =I28-I31-I34 -> 2386.7744 | J37: =J28-J31-J34 -> 2412.7161 | ... Q37: =Q28-Q31-Q34 -> 0
B38: ="% of "&$B$4 -> % of Revenue | C38: =IFERROR(C37/C$4,0) -> 0.047683056 | D38: =D37/D$4 -> 0.047724904 | E38: =E37/E$4 -> 0.064762269 | F38: =F37/F$4 -> 0.060770992 | G38: =G37/G$4 -> -0.012253929 | H38: =IFERROR(H37/H$4,0) -> 0.043952766 | I38: =IFERROR(I37/I$4,0) -> 0.044245486 | J38: =IFERROR(J37/J$4,0) -> 0.044283551 | K38: =IFERROR(K37/K$4,0) -> 0.044161315 | L38: =IFERROR(L37/L$4,0) -> 0.04411688 | M38: =IFERROR(M37/M$4,0) -> 0 | N38: =IFERROR(N37/N$4,0) -> 0 | O38: =IFERROR(O37/O$4,0) -> 0 | ... Q38: =IFERROR(Q37/Q$4,0) -> 0
B39: Year over Year Growth % | D39: =D37/C37-1 -> 0.019287834 | E39: =E37/D37-1 -> 0.47840854 | F39: =F37/E37-1 -> 0.062684608 | G39: =G37/F37-1 -> -1.2001235 | H39: =IF(H$3="",0,H37/G37-1) -> -4.6226989 | I39: =IF(I$3="",0,I37/H37-1) -> 0.016726471 | J39: =IF(J$3="",0,J37/I37-1) -> 0.010868916 | K39: =IF(K$3="",0,K37/J37-1) -> 0.0072120954 | L39: =IF(L$3="",0,L37/K37-1) -> 0.0089837612 | M39: =IF(M$3="",0,M37/L37-1) -> 0 | N39: =IF(N$3="",0,N37/M37-1) -> 0 | O39: =IF(O$3="",0,O37/N37-1) -> 0 | ... Q39: =IF(Q$3="",0,Q37/P37-1) -> 0
B42: EBITDA Calculation
B43: =B$22 -> Operating Income (Loss) ~ EBIT | C43: =C$22 -> 3063 | D43: =D$22 -> 2903 | E43: =E$22 -> 4248 | F43: =F$22 -> 4362 | G43: =G$22 -> 894 | H43: =H$22 -> 3509.19 | I43: =I$22 -> 3544.2819 | ... Q43: =Q$22 -> 0
B44: =Assumptions!B187 -> Capital Expenditures | C44: =Assumptions!D187 -> 1259 | D44: =Assumptions!E187 -> 1199 | E44: =Assumptions!F187 -> 1209 | F44: =Assumptions!G187 -> 1887 | G44: =Assumptions!H187 -> 1939 | H44: =H4*H45 -> 1658.1968 | I44: =I4*I45 -> 1674.7787 | J44: =J4*J45 -> 1691.5265 | K44: =K4*K45 -> 1708.4418 | L44: =L4*L45 -> 1725.5262 | M44: =M4*M45 -> 0 | N44: =N4*N45 -> 0 | O44: =O4*O45 -> 0 | ... Q44: =Q4*Q45 -> 0
B45: ="% of "&$B$4 -> % of Revenue | C45: =IFERROR(C44/C$4,0) -> 0.029689895 | D45: =D44/D$4 -> 0.02776427 | E45: =E44/E$4 -> 0.025696614 | F45: =F44/F$4 -> 0.035415337 | G45: =G44/G$4 -> 0.036667234 | H45: =Assumptions!I$188 -> 0.03104667 | I45: =Assumptions!J188 -> 0.03104667 | J45: =Assumptions!K188 -> 0.03104667 | K45: =Assumptions!L188 -> 0.03104667 | L45: =Assumptions!M188 -> 0.03104667 | M45: =Assumptions!N188 -> 0 | N45: =Assumptions!O188 -> 0 | O45: =Assumptions!P188 -> 0 | P45: =Assumptions!Q188 -> 0 | Q45: =Assumptions!R188 -> 0
B47: =Assumptions!B191 -> Depreciation and Amortization | C47: =Assumptions!D191 -> 1098 | D47: =Assumptions!E191 -> 1192 | E47: =Assumptions!F191 -> 1214 | F47: =Assumptions!G191 -> 1202 | G47: =Assumptions!H191 -> 1339 | H47: =H44*H49 -> 1392.2121 | I47: =I44*I49 -> 1406.1342 | J47: =J44*J49 -> 1420.1956 | K47: =K44*K49 -> 1434.3975 | L47: =L44*L49 -> 1448.7415 | M47: =M44*M49 -> 0 | N47: =N44*N49 -> 0 | O47: =O44*O49 -> 0 | ... Q47: =Q44*Q49 -> 0
B48: ="% of "&$B$4 -> % of Revenue | C48: =IFERROR(C47/C$4,0) -> 0.025893173 | D48: =D47/D$4 -> 0.027602177 | E48: =E47/E$4 -> 0.025802886 | F48: =F47/F$4 -> 0.022559213 | G48: =G47/G$4 -> 0.025321004 | H48: =IFERROR(H47/H$4,0) -> 0.0260666 | I48: =IFERROR(I47/I$4,0) -> 0.0260666 | J48: =IFERROR(J47/J$4,0) -> 0.0260666 | K48: =IFERROR(K47/K$4,0) -> 0.0260666 | L48: =IFERROR(L47/L$4,0) -> 0.0260666 | M48: =IFERROR(M47/M$4,0) -> 0 | N48: =IFERROR(N47/N$4,0) -> 0 | O48: =IFERROR(O47/O$4,0) -> 0 | ... Q48: =IFERROR(Q47/Q$4,0) -> 0
B49: ="% of "&B44 -> % of Capital Expenditures | C49: =IFERROR(C47/C44,0) -> 0.87212073 | D49: =IFERROR(D47/D44,0) -> 0.9941618 | E49: =IFERROR(E47/E44,0) -> 1.0041356 | F49: =IFERROR(F47/F44,0) -> 0.63698993 | G49: =IFERROR(G47/G44,0) -> 0.69056215 | H49: =Assumptions!I$192 -> 0.83959405 | I49: =Assumptions!J$192 -> 0.83959405 | J49: =Assumptions!K$192 -> 0.83959405 | K49: =Assumptions!L$192 -> 0.83959405 | L49: =Assumptions!M$192 -> 0.83959405 | M49: =Assumptions!N$192 -> 0 | N49: =Assumptions!O$192 -> 0 | O49: =Assumptions!P$192 -> 0 | ... Q49: =Assumptions!R$192 -> 0
B51: =_xlfn.TEXTBEFORE(Assumptions!B195," [") -> Cost of Capitalized Leases | C51: =Assumptions!D195 -> 0 | D51: =Assumptions!E195 -> 0 | E51: =Assumptions!F195 -> 0 | F51: =Assumptions!G195 -> 0 | G51: =Assumptions!H195 -> 0 | H51: =H$4*H52 -> 0 | I51: =I$4*I52 -> 0 | J51: =J$4*J52 -> 0 | K51: =K$4*K52 -> 0 | L51: =L$4*L52 -> 0 | M51: =M$4*M52 -> 0 | N51: =N$4*N52 -> 0 | O51: =O$4*O52 -> 0 | ... Q51: =Q$4*Q52 -> 0
B52: ="% of "&$B$4 -> % of Revenue | C52: =IFERROR(C51/C$4,0) -> 0 | D52: =D51/D$4 -> 0 | E52: =E51/E$4 -> 0 | F52: =F51/F$4 -> 0 | G52: =G51/G$4 -> 0 | H52: =+Assumptions!I196 -> 0 | I52: =+Assumptions!J196 -> 0 | J52: =+Assumptions!K196 -> 0 | K52: =+Assumptions!L196 -> 0 | L52: =+Assumptions!M196 -> 0 | M52: =+Assumptions!N196 -> 0 | N52: =+Assumptions!O196 -> 0 | O52: =+Assumptions!P196 -> 0 | ... Q52: =+Assumptions!R196 -> 0
B53: EBITDA | C53: =SUM(C43,C47,C51) -> 4161 | D53: =SUM(D43,D47,D51) -> 4095 | E53: =SUM(E43,E47,E51) -> 5462 | F53: =SUM(F43,F47,F51) -> 5564 | G53: =SUM(G43,G47,G51) -> 2233 | H53: =SUM(H43,H47,H51) -> 4901.4021 | I53: =SUM(I43,I47,I51) -> 4950.4161 | J53: =SUM(J43,J47,J51) -> 4999.9203 | ... Q53: =SUM(Q43,Q47,Q51) -> 0
B56: NOPAT Calculation
B57: =B$22 -> Operating Income (Loss) ~ EBIT | C57: =C$22 -> 3063 | D57: =D$22 -> 2903 | E57: =E$22 -> 4248 | F57: =F$22 -> 4362 | G57: =G$22 -> 894 | H57: =H$22 -> 3509.19 | I57: =I$22 -> 3544.2819 | ... Q57: =Q$22 -> 0
...

Sheet IS Bear
B2: Income Statement - Bear
B3: =Assumptions!$B$132 -> Year Ending 09/31/2024, In USD Millions | C3: {=_xlfn.SEQUENCE(1,5+Assumptions!$C$20,(YEAR('Valuation Summary'!$C$4)-5))} -> 2019 | D3: 2020 | E3: 2021 | F3: 2022 | G3: 2023 | H3: 2024 | I3: 2025 | J3: 2026 | K3: 2027 | L3: 2028
B4: =Assumptions!B136 -> Revenue | C4: =Assumptions!D136 -> 42405 | D4: =Assumptions!E136 -> 43185 | E4: =Assumptions!F136 -> 47049 | F4: =Assumptions!G136 -> 53282 | G4: =Assumptions!H136 -> 52881 | H4: =IF(H3="",0,G4*(1+H6)) -> 52352.19 | I4: =IF(I3="",0,H4*(1+I6)) -> 51828.668 | J4: =IF(J3="",0,I4*(1+J6)) -> 51310.381 | K4: =IF(K3="",0,J4*(1+K6)) -> 50797.278 | L4: =IF(L3="",0,K4*(1+L6)) -> 50289.305 | M4: =IF(M3="",0,L4*(1+M6)) -> 0 | N4: =IF(N3="",0,M4*(1+N6)) -> 0 | O4: =IF(O3="",0,N4*(1+O6)) -> 0 | ... Q4: =IF(Q3="",0,P4*(1+Q6)) -> 0
B5: ="% of "&$B$4 -> % of Revenue | C5: =IFERROR(C4/C$4,0) -> 1 | D5: =D4/D$4 -> 1 | E5: =E4/E$4 -> 1 | F5: =F4/F$4 -> 1 | G5: =G4/G$4 -> 1 | H5: =IFERROR(H4/H$4,0) -> 1 | I5: =IFERROR(I4/I$4,0) -> 1 | J5: =IFERROR(J4/J$4,0) -> 1 | K5: =IFERROR(K4/K$4,0) -> 1 | L5: =IFERROR(L4/L$4,0) -> 1 | M5: =IFERROR(M4/M$4,0) -> 0 | N5: =IFERROR(N4/N$4,0) -> 0 | O5: =IFERROR(O4/O$4,0) -> 0 | ... Q5: =IFERROR(Q4/Q$4,0) -> 0
B6: Year over Year Growth % | D6: =D4/C4-1 -> 0.018394057 | E6: =E4/D4-1 -> 0.089475512 | F6: =F4/E4-1 -> 0.1324789 | G6: =G4/F4-1 -> -0.0075259938 | H6: =Assumptions!I$138 -> -0.01 | I6: =Assumptions!J$138 -> -0.01 | J6: =Assumptions!K$138 -> -0.01 | K6: =Assumptions!L$138 -> -0.01 | L6: =Assumptions!M$138 -> -0.01 | M6: =Assumptions!N$138 -> 0 | N6: =Assumptions!O$138 -> 0 | O6: =Assumptions!P$138 -> 0 | ... Q6: =Assumptions!R$138 -> 0
